<?xml version="1.0" ?>
<!-- =================================================================================== -->
<!-- |    This document was autogenerated by xacro from /home/vaibhavi/SEE_ws/myseepackage/model/snake_bot.xacro | -->
<!-- |    EDITING THIS FILE BY HAND IS NOT RECOMMENDED                                 | -->
<!-- =================================================================================== -->
<robot name="snake_bot">
  <!-- Materials -->
  <material name="Blue">
    <color rgba="0.0 0.0 1.0 1.0"/>
  </material>
  <material name="Red">
    <color rgba="1.0 0.0 0.0 1.0"/>
  </material>
  <material name="Green">
    <color rgba="0.0 1.0 0.0 1.0"/>
  </material>
  <material name="Yellow">
    <color rgba="1.0 1.0 0.0 1.0"/>
  </material>
  <material name="Orange">
    <color rgba="1.0 0.5 0.0 1.0"/>
  </material>
  <material name="Purple">
    <color rgba="0.5 0.0 1.0 1.0"/>
  </material>
  <!-- Base Link -->
  <link name="base_link">
    <inertial>
      <origin xyz="0 0 0"/>
      <mass value="1.0"/>
      <inertia ixx="0.1" ixy="0.0" ixz="0.0" iyy="0.1" iyz="0.0" izz="0.1"/>
    </inertial>
    <visual>
      <geometry>
        <cylinder length="0.07" radius="0.03"/>
      </geometry>
      <origin rpy="0 1.57 0" xyz="0 0 0"/>
      <material name="Blue"/>
    </visual>
    <collision>
      <geometry>
        <cylinder length="0.07" radius="0.03"/>
      </geometry>
    </collision>
  </link>
  <gazebo reference="base_link">
    <material>Gazebo/Blue</material>
    <sensor name="camera_sensor" type="camera">
      <pose>0 0 0.1 0 0 0</pose>
      <camera>
        <horizontal_fov>1.047</horizontal_fov>
        <image>
          <width>640</width>
          <height>480</height>
          <format>R8G8B8</format>
        </image>
        <clip>
          <near>0.1</near>
          <far>100</far>
        </clip>
      </camera>
      <plugin filename="libgazebo_ros_camera.so" name="camera_controller">
        <ros>
          <namespace>/snake_bot</namespace>
          <remapping>image_raw:=/camera/image_raw</remapping>
        </ros>
        <update_rate>30.0</update_rate>
        <camera_name>snake_bot_camera</camera_name>
      </plugin>
    </sensor>
  </gazebo>
  <joint name="joint1" type="continuous">
    <parent link="base_link"/>
    <child link="link1"/>
    <origin rpy="0 0 0" xyz="0.1 0 0"/>
    <axis xyz="0 0 1"/>
    <limit effort="10.0" velocity="2.0"/>
  </joint>
  <gazebo reference="joint1">
    <provideFeedback>true</provideFeedback>
  </gazebo>
  <link name="link1">
    <inertial>
      <origin xyz="0 0 0"/>
      <mass value="0.5"/>
      <inertia ixx="0.01" ixy="0.0" ixz="0.0" iyy="0.01" iyz="0.0" izz="0.01"/>
    </inertial>
    <visual>
      <geometry>
        <cylinder length="0.07" radius="0.03"/>
      </geometry>
      <origin rpy="0 1.57 0" xyz="0 0 0"/>
      <material name="Purple"/>
    </visual>
    <collision>
      <geometry>
        <cylinder length="0.07" radius="0.03"/>
      </geometry>
    </collision>
  </link>
  <gazebo reference="link1">
    <material>Gazebo/Purple</material>
  </gazebo>
  <joint name="joint2" type="continuous">
    <parent link="link1"/>
    <child link="link2"/>
    <origin rpy="0 0 0" xyz="0.1 0 0"/>
    <axis xyz="0 0 1"/>
    <limit effort="10.0" velocity="2.0"/>
  </joint>
  <gazebo reference="joint2">
    <provideFeedback>true</provideFeedback>
  </gazebo>
  <link name="link2">
    <inertial>
      <origin xyz="0 0 0"/>
      <mass value="0.5"/>
      <inertia ixx="0.01" ixy="0.0" ixz="0.0" iyy="0.01" iyz="0.0" izz="0.01"/>
    </inertial>
    <visual>
      <geometry>
        <cylinder length="0.07" radius="0.03"/>
      </geometry>
      <origin rpy="0 1.57 0" xyz="0 0 0"/>
      <material name="Red"/>
    </visual>
    <collision>
      <geometry>
        <cylinder length="0.07" radius="0.03"/>
      </geometry>
    </collision>
  </link>
  <gazebo reference="link2">
    <material>Gazebo/Red</material>
  </gazebo>
  <joint name="joint3" type="continuous">
    <parent link="link2"/>
    <child link="link3"/>
    <origin rpy="0 0 0" xyz="0.1 0 0"/>
    <axis xyz="0 0 1"/>
    <limit effort="10.0" velocity="2.0"/>
  </joint>
  <gazebo reference="joint3">
    <provideFeedback>true</provideFeedback>
  </gazebo>
  <link name="link3">
    <inertial>
      <origin xyz="0 0 0"/>
      <mass value="0.5"/>
      <inertia ixx="0.01" ixy="0.0" ixz="0.0" iyy="0.01" iyz="0.0" izz="0.01"/>
    </inertial>
    <visual>
      <geometry>
        <cylinder length="0.07" radius="0.03"/>
      </geometry>
      <origin rpy="0 1.57 0" xyz="0 0 0"/>
      <material name="Green"/>
    </visual>
    <collision>
      <geometry>
        <cylinder length="0.07" radius="0.03"/>
      </geometry>
    </collision>
  </link>
  <gazebo reference="link3">
    <material>Gazebo/Green</material>
  </gazebo>
  <joint name="joint4" type="continuous">
    <parent link="link3"/>
    <child link="link4"/>
    <origin rpy="0 0 0" xyz="0.1 0 0"/>
    <axis xyz="0 0 1"/>
    <limit effort="10.0" velocity="2.0"/>
  </joint>
  <gazebo reference="joint4">
    <provideFeedback>true</provideFeedback>
  </gazebo>
  <link name="link4">
    <inertial>
      <origin xyz="0 0 0"/>
      <mass value="0.5"/>
      <inertia ixx="0.01" ixy="0.0" ixz="0.0" iyy="0.01" iyz="0.0" izz="0.01"/>
    </inertial>
    <visual>
      <geometry>
        <cylinder length="0.07" radius="0.03"/>
      </geometry>
      <origin rpy="0 1.57 0" xyz="0 0 0"/>
      <material name="Yellow"/>
    </visual>
    <collision>
      <geometry>
        <cylinder length="0.07" radius="0.03"/>
      </geometry>
    </collision>
  </link>
  <gazebo reference="link4">
    <material>Gazebo/Yellow</material>
  </gazebo>
  <joint name="joint5" type="continuous">
    <parent link="link4"/>
    <child link="link5"/>
    <origin rpy="0 0 0" xyz="0.1 0 0"/>
    <axis xyz="0 0 1"/>
    <limit effort="10.0" velocity="2.0"/>
  </joint>
  <gazebo reference="joint5">
    <provideFeedback>true</provideFeedback>
  </gazebo>
  <link name="link5">
    <inertial>
      <origin xyz="0 0 0"/>
      <mass value="0.5"/>
      <inertia ixx="0.01" ixy="0.0" ixz="0.0" iyy="0.01" iyz="0.0" izz="0.01"/>
    </inertial>
    <visual>
      <geometry>
        <cylinder length="0.07" radius="0.03"/>
      </geometry>
      <origin rpy="0 1.57 0" xyz="0 0 0"/>
      <material name="Orange"/>
    </visual>
    <collision>
      <geometry>
        <cylinder length="0.07" radius="0.03"/>
      </geometry>
    </collision>
  </link>
  <gazebo reference="link5">
    <material>Gazebo/Orange</material>
  </gazebo>
  <joint name="joint6" type="continuous">
    <parent link="link5"/>
    <child link="link6"/>
    <origin rpy="0 0 0" xyz="0.1 0 0"/>
    <axis xyz="0 0 1"/>
    <limit effort="10.0" velocity="2.0"/>
  </joint>
  <gazebo reference="joint6">
    <provideFeedback>true</provideFeedback>
  </gazebo>
  <link name="link6">
    <inertial>
      <origin xyz="0 0 0"/>
      <mass value="0.5"/>
      <inertia ixx="0.01" ixy="0.0" ixz="0.0" iyy="0.01" iyz="0.0" izz="0.01"/>
    </inertial>
    <visual>
      <geometry>
        <cylinder length="0.07" radius="0.03"/>
      </geometry>
      <origin rpy="0 1.57 0" xyz="0 0 0"/>
      <material name="Blue"/>
    </visual>
    <collision>
      <geometry>
        <cylinder length="0.07" radius="0.03"/>
      </geometry>
    </collision>
  </link>
  <gazebo reference="link6">
    <material>Gazebo/Blue</material>
  </gazebo>
  <gazebo reference="link6">
    <material>Gazebo/Blue</material>
    <sensor name="camera_sensor_link6" type="camera">
      <pose>0 0 0.1 0 0 0</pose>
      <camera>
        <horizontal_fov>1.047</horizontal_fov>
        <image>
          <width>640</width>
          <height>480</height>
          <format>R8G8B8</format>
        </image>
        <clip>
          <near>0.1</near>
          <far>100</far>
        </clip>
      </camera>
      <plugin filename="libgazebo_ros_camera.so" name="camera_controller_link6">
        <ros>
          <namespace>/snake_bot</namespace>
          <remapping>image_raw:=/camera/link6/image_raw</remapping>
        </ros>
        <update_rate>30.0</update_rate>
        <camera_name>snake_bot_camera_link6</camera_name>
      </plugin>
    </sensor>
  </gazebo>
</robot>
